Workbook

Sheet Data
A1: Trader ID | B1: Country | C1: City | D1: Reporting_week | E1: Successful transactions | F1: Failed transactions | G1: Gross_bookings | H1: Currency
A2: 13ba2434-3f15-4a6c-8fb2-971d4edbc878 | B2: Poland | C2: Gdansk | D2: 45663 | E2: 16 | F2: 0 | G2: 1875 | H2: =VLOOKUP(B2,'Currency Table'!$M$3:$N$6,2, FALSE) -> PLN
A3: d3f25e71-f59d-4281-b78a-c559b5e1d9e3 | B3: Poland | C3: Wroclaw | D3: 45663 | E3: 15 | F3: 0 | G3: 874 | H3: =VLOOKUP(B3,'Currency Table'!$M$3:$N$6,2, FALSE) -> PLN
A4: f7388d83-5906-4df5-9fc9-5ee5438f0a5d | B4: Poland | C4: Lodz | D4: 45663 | E4: 32 | F4: 3 | G4: 2269 | H4: =VLOOKUP(B4,'Currency Table'!$M$3:$N$6,2, FALSE) -> PLN
A5: 39f3a680-56e7-4b2b-a706-94319a1da61e | B5: Poland | C5: Warsaw | D5: 45663 | E5: 11 | F5: 0 | G5: 658 | H5: =VLOOKUP(B5,'Currency Table'!$M$3:$N$6,2, FALSE) -> PLN
A6: 63dc8854-5507-4bbc-b2e0-73e312a05bef | B6: Poland | C6: Warsaw | D6: 45663 | E6: 51 | F6: 0 | G6: 3721 | H6: =VLOOKUP(B6,'Currency Table'!$M$3:$N$6,2, FALSE) -> PLN
A7: 1308203b-4a46-4f50-b4d7-a762dfe62146 | B7: Poland | C7: Wroclaw | D7: 45663 | E7: 55 | F7: 3 | G7: 3377 | H7: =VLOOKUP(B7,'Currency Table'!$M$3:$N$6,2, FALSE) -> PLN
A8: c2d1b451-32e8-458b-98f7-bbacb52cf739 | B8: Poland | C8: Lodz | D8: 45663 | E8: 68 | F8: 5 | G8: 4142 | H8: =VLOOKUP(B8,'Currency Table'!$M$3:$N$6,2, FALSE) -> PLN
A9: 6a741918-1ba5-462d-963a-96bd8bc0cd7f | B9: Poland | C9: Wroclaw | D9: 45663 | E9: 45 | F9: 4 | G9: 2716 | H9: =VLOOKUP(B9,'Currency Table'!$M$3:$N$6,2, FALSE) -> PLN
A10: f66db0dd-6f7d-4438-a70f-3a452f276824 | B10: Poland | C10: Warsaw | D10: 45663 | E10: 17 | F10: 4 | G10: 1604 | H10: =VLOOKUP(B10,'Currency Table'!$M$3:$N$6,2, FALSE) -> PLN
A11: 6300619f-2b1f-47e2-bb23-c43e45bca55d | B11: Poland | C11: Krakow | D11: 45663 | E11: 15 | F11: 3 | G11: 865 | H11: =VLOOKUP(B11,'Currency Table'!$M$3:$N$6,2, FALSE) -> PLN
A12: d6493a28-7324-4884-a0e8-b453f98ede84 | B12: Poland | C12: Krakow | D12: 45663 | E12: 31 | F12: 2 | G12: 2463 | H12: =VLOOKUP(B12,'Currency Table'!$M$3:$N$6,2, FALSE) -> PLN
A13: a9ffd244-5521-4aa2-983d-fcad2b2737b6 | B13: Poland | C13: Gdansk | D13: 45663 | E13: 10 | F13: 0 | G13: 685 | H13: =VLOOKUP(B13,'Currency Table'!$M$3:$N$6,2, FALSE) -> PLN
... A1444: 08764762-0a2f-4f4e-b3e6-6067d3c70d7a | B1444: Spain | C1444: Alicante | D1444: 45684 | E1444: 15 | F1444: 0 | G1444: 236 | H1444: =VLOOKUP(B1444,'Currency Table'!$M$3:$N$6,2, FALSE) -> EUR

Sheet Currency Table
M2: Country | N2: Currency
M3: Poland | N3: PLN
M4: Spain | N4: EUR
M5: UK | N5: GBP
M6: France | N6: EUR

Sheet GQuery
A1: =IFERROR(__xludf.DUMMYFUNCTION("QUERY(Data!A1:H1444, ""select A, C, D, E, E*G, H where E > 50 label E*G 'Overall gross bookings'"")"),"Trader ID") -> Trader ID | B1: =IFERROR(__xludf.DUMMYFUNCTION("""COMPUTED_VALUE"""),"City") -> City | C1: =IFERROR(__xludf.DUMMYFUNCTION("""COMPUTED_VALUE"""),"Reporting_week") -> Reporting_week | D1: =IFERROR(__xludf.DUMMYFUNCTION("""COMPUTED_VALUE"""),"Successful transactions") -> Successful transactions | E1: =IFERROR(__xludf.DUMMYFUNCTION("""COMPUTED_VALUE"""),"Overall gross bookings") -> Overall gross bookings | F1: =IFERROR(__xludf.DUMMYFUNCTION("""COMPUTED_VALUE"""),"Currency") -> Currency
A2: =IFERROR(__xludf.DUMMYFUNCTION("""COMPUTED_VALUE"""),"63dc8854-5507-4bbc-b2e0-73e312a05bef") -> 63dc8854-5507-4bbc-b2e0-73e312a05bef | B2: =IFERROR(__xludf.DUMMYFUNCTION("""COMPUTED_VALUE"""),"Warsaw") -> Warsaw | C2: =IFERROR(__xludf.DUMMYFUNCTION("""COMPUTED_VALUE"""),45663.0) -> 45663 | D2: =IFERROR(__xludf.DUMMYFUNCTION("""COMPUTED_VALUE"""),51.0) -> 51 | E2: =IFERROR(__xludf.DUMMYFUNCTION("""COMPUTED_VALUE"""),189771.0) -> 189771 | F2: =IFERROR(__xludf.DUMMYFUNCTION("""COMPUTED_VALUE"""),"PLN") -> PLN
A3: =IFERROR(__xludf.DUMMYFUNCTION("""COMPUTED_VALUE"""),"1308203b-4a46-4f50-b4d7-a762dfe62146") -> 1308203b-4a46-4f50-b4d7-a762dfe62146 | B3: =IFERROR(__xludf.DUMMYFUNCTION("""COMPUTED_VALUE"""),"Wroclaw") -> Wroclaw | C3: =IFERROR(__xludf.DUMMYFUNCTION("""COMPUTED_VALUE"""),45663.0) -> 45663 | D3: =IFERROR(__xludf.DUMMYFUNCTION("""COMPUTED_VALUE"""),55.0) -> 55 | E3: =IFERROR(__xludf.DUMMYFUNCTION("""COMPUTED_VALUE"""),185735.0) -> 185735 | F3: =IFERROR(__xludf.DUMMYFUNCTION("""COMPUTED_VALUE"""),"PLN") -> PLN
A4: =IFERROR(__xludf.DUMMYFUNCTION("""COMPUTED_VALUE"""),"c2d1b451-32e8-458b-98f7-bbacb52cf739") -> c2d1b451-32e8-458b-98f7-bbacb52cf739 | B4: =IFERROR(__xludf.DUMMYFUNCTION("""COMPUTED_VALUE"""),"Lodz") -> Lodz | C4: =IFERROR(__xludf.DUMMYFUNCTION("""COMPUTED_VALUE"""),45663.0) -> 45663 | D4: =IFERROR(__xludf.DUMMYFUNCTION("""COMPUTED_VALUE"""),68.0) -> 68 | E4: =IFERROR(__xludf.DUMMYFUNCTION("""COMPUTED_VALUE"""),281656.0) -> 281656 | F4: =IFERROR(__xludf.DUMMYFUNCTION("""COMPUTED_VALUE"""),"PLN") -> PLN
A5: =IFERROR(__xludf.DUMMYFUNCTION("""COMPUTED_VALUE"""),"96f5ac8f-4723-47f4-8300-380ed21bc6e7") -> 96f5ac8f-4723-47f4-8300-380ed21bc6e7 | B5: =IFERROR(__xludf.DUMMYFUNCTION("""COMPUTED_VALUE"""),"Poznan") -> Poznan | C5: =IFERROR(__xludf.DUMMYFUNCTION("""COMPUTED_VALUE"""),45663.0) -> 45663 | D5: =IFERROR(__xludf.DUMMYFUNCTION("""COMPUTED_VALUE"""),62.0) -> 62 | E5: =IFERROR(__xludf.DUMMYFUNCTION("""COMPUTED_VALUE"""),277946.0) -> 277946 | F5: =IFERROR(__xludf.DUMMYFUNCTION("""COMPUTED_VALUE"""),"PLN") -> PLN
A6: =IFERROR(__xludf.DUMMYFUNCTION("""COMPUTED_VALUE"""),"e45cfd06-5301-4af4-858d-54ca4de59f79") -> e45cfd06-5301-4af4-858d-54ca4de59f79 | B6: =IFERROR(__xludf.DUMMYFUNCTION("""COMPUTED_VALUE"""),"Gdansk") -> Gdansk | C6: =IFERROR(__xludf.DUMMYFUNCTION("""COMPUTED_VALUE"""),45663.0) -> 45663 | D6: =IFERROR(__xludf.DUMMYFUNCTION("""COMPUTED_VALUE"""),61.0) -> 61 | E6: =IFERROR(__xludf.DUMMYFUNCTION("""COMPUTED_VALUE"""),240340.0) -> 240340 | F6: =IFERROR(__xludf.DUMMYFUNCTION("""COMPUTED_VALUE"""),"PLN") -> PLN
A7: =IFERROR(__xludf.DUMMYFUNCTION("""COMPUTED_VALUE"""),"0a062c77-77f1-40bb-bf75-23b37aaa17ea") -> 0a062c77-77f1-40bb-bf75-23b37aaa17ea | B7: =IFERROR(__xludf.DUMMYFUNCTION("""COMPUTED_VALUE"""),"Gdansk") -> Gdansk | C7: =IFERROR(__xludf.DUMMYFUNCTION("""COMPUTED_VALUE"""),45663.0) -> 45663 | D7: =IFERROR(__xludf.DUMMYFUNCTION("""COMPUTED_VALUE"""),64.0) -> 64 | E7: =IFERROR(__xludf.DUMMYFUNCTION("""COMPUTED_VALUE"""),254656.0) -> 254656 | F7: =IFERROR(__xludf.DUMMYFUNCTION("""COMPUTED_VALUE"""),"PLN") -> PLN
A8: =IFERROR(__xludf.DUMMYFUNCTION("""COMPUTED_VALUE"""),"0249f184-5b67-469d-a05e-ab2f7f7af959") -> 0249f184-5b67-469d-a05e-ab2f7f7af959 | B8: =IFERROR(__xludf.DUMMYFUNCTION("""COMPUTED_VALUE"""),"Krakow") -> Krakow | C8: =IFERROR(__xludf.DUMMYFUNCTION("""COMPUTED_VALUE"""),45663.0) -> 45663 | D8: =IFERROR(__xludf.DUMMYFUNCTION("""COMPUTED_VALUE"""),62.0) -> 62 | E8: =IFERROR(__xludf.DUMMYFUNCTION("""COMPUTED_VALUE"""),272614.0) -> 272614 | F8: =IFERROR(__xludf.DUMMYFUNCTION("""COMPUTED_VALUE"""),"PLN") -> PLN
A9: =IFERROR(__xludf.DUMMYFUNCTION("""COMPUTED_VALUE"""),"993236a1-4fa5-4249-9228-af02bedc5a3a") -> 993236a1-4fa5-4249-9228-af02bedc5a3a | B9: =IFERROR(__xludf.DUMMYFUNCTION("""COMPUTED_VALUE"""),"Poznan") -> Poznan | C9: =IFERROR(__xludf.DUMMYFUNCTION("""COMPUTED_VALUE"""),45663.0) -> 45663 | D9: =IFERROR(__xludf.DUMMYFUNCTION("""COMPUTED_VALUE"""),66.0) -> 66 | E9: =IFERROR(__xludf.DUMMYFUNCTION("""COMPUTED_VALUE"""),258720.0) -> 258720 | F9: =IFERROR(__xludf.DUMMYFUNCTION("""COMPUTED_VALUE"""),"PLN") -> PLN
A10: =IFERROR(__xludf.DUMMYFUNCTION("""COMPUTED_VALUE"""),"fa37b3f0-bbbe-4fe2-8e65-93529e065ddc") -> fa37b3f0-bbbe-4fe2-8e65-93529e065ddc | B10: =IFERROR(__xludf.DUMMYFUNCTION("""COMPUTED_VALUE"""),"Warsaw") -> Warsaw | C10: =IFERROR(__xludf.DUMMYFUNCTION("""COMPUTED_VALUE"""),45663.0) -> 45663 | D10: =IFERROR(__xludf.DUMMYFUNCTION("""COMPUTED_VALUE"""),53.0) -> 53 | E10: =IFERROR(__xludf.DUMMYFUNCTION("""COMPUTED_VALUE"""),205481.0) -> 205481 | F10: =IFERROR(__xludf.DUMMYFUNCTION("""COMPUTED_VALUE"""),"PLN") -> PLN
A11: =IFERROR(__xludf.DUMMYFUNCTION("""COMPUTED_VALUE"""),"fb3a15c1-d3c3-4f4f-b8ed-2113bd9c4f68") -> fb3a15c1-d3c3-4f4f-b8ed-2113bd9c4f68 | B11: =IFERROR(__xludf.DUMMYFUNCTION("""COMPUTED_VALUE"""),"Warsaw") -> Warsaw | C11: =IFERROR(__xludf.DUMMYFUNCTION("""COMPUTED_VALUE"""),45663.0) -> 45663 | D11: =IFERROR(__xludf.DUMMYFUNCTION("""COMPUTED_VALUE"""),58.0) -> 58 | E11: =IFERROR(__xludf.DUMMYFUNCTION("""COMPUTED_VALUE"""),195692.0) -> 195692 | F11: =IFERROR(__xludf.DUMMYFUNCTION("""COMPUTED_VALUE"""),"PLN") -> PLN
A12: =IFERROR(__xludf.DUMMYFUNCTION("""COMPUTED_VALUE"""),"8366c09f-fd56-4a04-946e-3d1fad10d00a") -> 8366c09f-fd56-4a04-946e-3d1fad10d00a | B12: =IFERROR(__xludf.DUMMYFUNCTION("""COMPUTED_VALUE"""),"Lodz") -> Lodz | C12: =IFERROR(__xludf.DUMMYFUNCTION("""COMPUTED_VALUE"""),45663.0) -> 45663 | D12: =IFERROR(__xludf.DUMMYFUNCTION("""COMPUTED_VALUE"""),51.0) -> 51 | E12: =IFERROR(__xludf.DUMMYFUNCTION("""COMPUTED_VALUE"""),197115.0) -> 197115 | F12: =IFERROR(__xludf.DUMMYFUNCTION("""COMPUTED_VALUE"""),"PLN") -> PLN
A13: =IFERROR(__xludf.DUMMYFUNCTION("""COMPUTED_VALUE"""),"6a10af0e-e274-406a-ad5e-a931989b2e20") -> 6a10af0e-e274-406a-ad5e-a931989b2e20 | B13: =IFERROR(__xludf.DUMMYFUNCTION("""COMPUTED_VALUE"""),"Warsaw") -> Warsaw | C13: =IFERROR(__xludf.DUMMYFUNCTION("""COMPUTED_VALUE"""),45663.0) -> 45663 | D13: =IFERROR(__xludf.DUMMYFUNCTION("""COMPUTED_VALUE"""),56.0) -> 56 | E13: =IFERROR(__xludf.DUMMYFUNCTION("""COMPUTED_VALUE"""),191632.0) -> 191632 | F13: =IFERROR(__xludf.DUMMYFUNCTION("""COMPUTED_VALUE"""),"PLN") -> PLN
A14: =IFERROR(__xludf.DUMMYFUNCTION("""COMPUTED_VALUE"""),"bf4c1c3b-77b0-4bc6-aff9-2062d5747e79") -> bf4c1c3b-77b0-4bc6-aff9-2062d5747e79 | B14: =IFERROR(__xludf.DUMMYFUNCTION("""COMPUTED_VALUE"""),"Krakow") -> Krakow | C14: =IFERROR(__xludf.DUMMYFUNCTION("""COMPUTED_VALUE"""),45663.0) -> 45663 | D14: =IFERROR(__xludf.DUMMYFUNCTION("""COMPUTED_VALUE"""),52.0) -> 52 | E14: =IFERROR(__xludf.DUMMYFUNCTION("""COMPUTED_VALUE"""),193232.0) -> 193232 | F14: =IFERROR(__xludf.DUMMYFUNCTION("""COMPUTED_VALUE"""),"PLN") -> PLN
A15: =IFERROR(__xludf.DUMMYFUNCTION("""COMPUTED_VALUE"""),"ecc16b34-df78-42ba-9a83-bf5ca441db00") -> ecc16b34-df78-42ba-9a83-bf5ca441db00 | B15: =IFERROR(__xludf.DUMMYFUNCTION("""COMPUTED_VALUE"""),"Lodz") -> Lodz | C15: =IFERROR(__xludf.DUMMYFUNCTION("""COMPUTED_VALUE"""),45663.0) -> 45663 | D15: =IFERROR(__xludf.DUMMYFUNCTION("""COMPUTED_VALUE"""),55.0) -> 55 | E15: =IFERROR(__xludf.DUMMYFUNCTION("""COMPUTED_VALUE"""),195690.0) -> 195690 | F15: =IFERROR(__xludf.DUMMYFUNCTION("""COMPUTED_VALUE"""),"PLN") -> PLN
A16: =IFERROR(__xludf.DUMMYFUNCTION("""COMPUTED_VALUE"""),"d894e29d-c9ec-43fc-94ce-f6b4d1b81294") -> d894e29d-c9ec-43fc-94ce-f6b4d1b81294 | B16: =IFERROR(__xludf.DUMMYFUNCTION("""COMPUTED_VALUE"""),"Wroclaw") -> Wroclaw | C16: =IFERROR(__xludf.DUMMYFUNCTION("""COMPUTED_VALUE"""),45663.0) -> 45663 | D16: =IFERROR(__xludf.DUMMYFUNCTION("""COMPUTED_VALUE"""),68.0) -> 68 | E16: =IFERROR(__xludf.DUMMYFUNCTION("""COMPUTED_VALUE"""),276284.0) -> 276284 | F16: =IFERROR(__xludf.DUMMYFUNCTION("""COMPUTED_VALUE"""),"PLN") -> PLN
A17: =IFERROR(__xludf.DUMMYFUNCTION("""COMPUTED_VALUE"""),"d781564c-61ae-4ed2-99d4-765e00b4801e") -> d781564c-61ae-4ed2-99d4-765e00b4801e | B17: =IFERROR(__xludf.DUMMYFUNCTION("""COMPUTED_VALUE"""),"Krakow") -> Krakow | C17: =IFERROR(__xludf.DUMMYFUNCTION("""COMPUTED_VALUE"""),45663.0) -> 45663 | D17: =IFERROR(__xludf.DUMMYFUNCTION("""COMPUTED_VALUE"""),65.0) -> 65 | E17: =IFERROR(__xludf.DUMMYFUNCTION("""COMPUTED_VALUE"""),270660.0) -> 270660 | F17: =IFERROR(__xludf.DUMMYFUNCTION("""COMPUTED_VALUE"""),"PLN") -> PLN
A18: =IFERROR(__xludf.DUMMYFUNCTION("""COMPUTED_VALUE"""),"47e81ae8-19b8-4512-86e4-d96a17e44d38") -> 47e81ae8-19b8-4512-86e4-d96a17e44d38 | B18: =IFERROR(__xludf.DUMMYFUNCTION("""COMPUTED_VALUE"""),"Gdansk") -> Gdansk | C18: =IFERROR(__xludf.DUMMYFUNCTION("""COMPUTED_VALUE"""),45663.0) -> 45663 | D18: =IFERROR(__xludf.DUMMYFUNCTION("""COMPUTED_VALUE"""),67.0) -> 67 | E18: =IFERROR(__xludf.DUMMYFUNCTION("""COMPUTED_VALUE"""),283477.0) -> 283477 | F18: =IFERROR(__xludf.DUMMYFUNCTION("""COMPUTED_VALUE"""),"PLN") -> PLN
A19: =IFERROR(__xludf.DUMMYFUNCTION("""COMPUTED_VALUE"""),"040b5c57-bbcd-491e-9168-21b2d807f924") -> 040b5c57-bbcd-491e-9168-21b2d807f924 | B19: =IFERROR(__xludf.DUMMYFUNCTION("""COMPUTED_VALUE"""),"Lodz") -> Lodz | C19: =IFERROR(__xludf.DUMMYFUNCTION("""COMPUTED_VALUE"""),45663.0) -> 45663 | D19: =IFERROR(__xludf.DUMMYFUNCTION("""COMPUTED_VALUE"""),62.0) -> 62 | E19: =IFERROR(__xludf.DUMMYFUNCTION("""COMPUTED_VALUE"""),246078.0) -> 246078 | F19: =IFERROR(__xludf.DUMMYFUNCTION("""COMPUTED_VALUE"""),"PLN") -> PLN
A20: =IFERROR(__xludf.DUMMYFUNCTION("""COMPUTED_VALUE"""),"aa51a7a1-a778-4464-ba35-408ed0d06819") -> aa51a7a1-a778-4464-ba35-408ed0d06819 | B20: =IFERROR(__xludf.DUMMYFUNCTION("""COMPUTED_VALUE"""),"Warsaw") -> Warsaw | C20: =IFERROR(__xludf.DUMMYFUNCTION("""COMPUTED_VALUE"""),45663.0) -> 45663 | D20: =IFERROR(__xludf.DUMMYFUNCTION("""COMPUTED_VALUE"""),60.0) -> 60 | E20: =IFERROR(__xludf.DUMMYFUNCTION("""COMPUTED_VALUE"""),217260.0) -> 217260 | F20: =IFERROR(__xludf.DUMMYFUNCTION("""COMPUTED_VALUE"""),"PLN") -> PLN
A21: =IFERROR(__xludf.DUMMYFUNCTION("""COMPUTED_VALUE"""),"31b85576-c3ee-484b-978e-8e2cb84c955e") -> 31b85576-c3ee-484b-978e-8e2cb84c955e | B21: =IFERROR(__xludf.DUMMYFUNCTION("""COMPUTED_VALUE"""),"Poznan") -> Poznan | C21: =IFERROR(__xludf.DUMMYFUNCTION("""COMPUTED_VALUE"""),45663.0) -> 45663 | D21: =IFERROR(__xludf.DUMMYFUNCTION("""COMPUTED_VALUE"""),59.0) -> 59 | E21: =IFERROR(__xludf.DUMMYFUNCTION("""COMPUTED_VALUE"""),220011.0) -> 220011 | F21: =IFERROR(__xludf.DUMMYFUNCTION("""COMPUTED_VALUE"""),"PLN") -> PLN
A22: =IFERROR(__xludf.DUMMYFUNCTION("""COMPUTED_VALUE"""),"d1c277ca-161d-4581-9fc7-b3114d590712") -> d1c277ca-161d-4581-9fc7-b3114d590712 | B22: =IFERROR(__xludf.DUMMYFUNCTION("""COMPUTED_VALUE"""),"Warsaw") -> Warsaw | C22: =IFERROR(__xludf.DUMMYFUNCTION("""COMPUTED_VALUE"""),45663.0) -> 45663 | D22: =IFERROR(__xludf.DUMMYFUNCTION("""COMPUTED_VALUE"""),55.0) -> 55 | E22: =IFERROR(__xludf.DUMMYFUNCTION("""COMPUTED_VALUE"""),186450.0) -> 186450 | F22: =IFERROR(__xludf.DUMMYFUNCTION("""COMPUTED_VALUE"""),"PLN") -> PLN
A23: =IFERROR(__xludf.DUMMYFUNCTION("""COMPUTED_VALUE"""),"7a6aca2a-2fb8-4dc1-a6b2-4723b607bbb8") -> 7a6aca2a-2fb8-4dc1-a6b2-4723b607bbb8 | B23: =IFERROR(__xludf.DUMMYFUNCTION("""COMPUTED_VALUE"""),"Wroclaw") -> Wroclaw | C23: =IFERROR(__xludf.DUMMYFUNCTION("""COMPUTED_VALUE"""),45663.0) -> 45663 | D23: =IFERROR(__xludf.DUMMYFUNCTION("""COMPUTED_VALUE"""),67.0) -> 67 | E23: =IFERROR(__xludf.DUMMYFUNCTION("""COMPUTED_VALUE"""),290914.0) -> 290914 | F23: =IFERROR(__xludf.DUMMYFUNCTION("""COMPUTED_VALUE"""),"PLN") -> PLN
A24: =IFERROR(__xludf.DUMMYFUNCTION("""COMPUTED_VALUE"""),"03568fa1-9357-405b-8fa9-cc136f9b5391") -> 03568fa1-9357-405b-8fa9-cc136f9b5391 | B24: =IFERROR(__xludf.DUMMYFUNCTION("""COMPUTED_VALUE"""),"Warsaw") -> Warsaw | C24: =IFERROR(__xludf.DUMMYFUNCTION("""COMPUTED_VALUE"""),45663.0) -> 45663 | D24: =IFERROR(__xludf.DUMMYFUNCTION("""COMPUTED_VALUE"""),54.0) -> 54 | E24: =IFERROR(__xludf.DUMMYFUNCTION("""COMPUTED_VALUE"""),199368.0) -> 199368 | F24: =IFERROR(__xludf.DUMMYFUNCTION("""COMPUTED_VALUE"""),"PLN") -> PLN
A25: =IFERROR(__xludf.DUMMYFUNCTION("""COMPUTED_VALUE"""),"55542419-044e-4cd7-84e6-975780911173") -> 55542419-044e-4cd7-84e6-975780911173 | B25: =IFERROR(__xludf.DUMMYFUNCTION("""COMPUTED_VALUE"""),"Wroclaw") -> Wroclaw | C25: =IFERROR(__xludf.DUMMYFUNCTION("""COMPUTED_VALUE"""),45663.0) -> 45663 | D25: =IFERROR(__xludf.DUMMYFUNCTION("""COMPUTED_VALUE"""),55.0) -> 55 | E25: =IFERROR(__xludf.DUMMYFUNCTION("""COMPUTED_VALUE"""),166925.0) -> 166925 | F25: =IFERROR(__xludf.DUMMYFUNCTION("""COMPUTED_VALUE"""),"PLN") -> PLN
A26: =IFERROR(__xludf.DUMMYFUNCTION("""COMPUTED_VALUE"""),"14768b32-9c82-4e5c-b220-443f5b19e3e3") -> 14768b32-9c82-4e5c-b220-443f5b19e3e3 | B26: =IFERROR(__xludf.DUMMYFUNCTION("""COMPUTED_VALUE"""),"Gdansk") -> Gdansk | C26: =IFERROR(__xludf.DUMMYFUNCTION("""COMPUTED_VALUE"""),45663.0) -> 45663 | D26: =IFERROR(__xludf.DUMMYFUNCTION("""COMPUTED_VALUE"""),56.0) -> 56 | E26: =IFERROR(__xludf.DUMMYFUNCTION("""COMPUTED_VALUE"""),215208.0) -> 215208 | F26: =IFERROR(__xludf.DUMMYFUNCTION("""COMPUTED_VALUE"""),"PLN") -> PLN
A27: =IFERROR(__xludf.DUMMYFUNCTION("""COMPUTED_VALUE"""),"caa3110f-e624-4f30-88e9-6f88f1b71129") -> caa3110f-e624-4f30-88e9-6f88f1b71129 | B27: =IFERROR(__xludf.DUMMYFUNCTION("""COMPUTED_VALUE"""),"Warsaw") -> Warsaw | C27: =IFERROR(__xludf.DUMMYFUNCTION("""COMPUTED_VALUE"""),45663.0) -> 45663 | D27: =IFERROR(__xludf.DUMMYFUNCTION("""COMPUTED_VALUE"""),61.0) -> 61 | E27: =IFERROR(__xludf.DUMMYFUNCTION("""COMPUTED_VALUE"""),269498.0) -> 269498 | F27: =IFERROR(__xludf.DUMMYFUNCTION("""COMPUTED_VALUE"""),"PLN") -> PLN
A28: =IFERROR(__xludf.DUMMYFUNCTION("""COMPUTED_VALUE"""),"0efa2ab0-07dd-4cc1-a6ff-6cd205147227") -> 0efa2ab0-07dd-4cc1-a6ff-6cd205147227 | B28: =IFERROR(__xludf.DUMMYFUNCTION("""COMPUTED_VALUE"""),"Poznan") -> Poznan | C28: =IFERROR(__xludf.DUMMYFUNCTION("""COMPUTED_VALUE"""),45663.0) -> 45663 | D28: =IFERROR(__xludf.DUMMYFUNCTION("""COMPUTED_VALUE"""),67.0) -> 67 | E28: =IFERROR(__xludf.DUMMYFUNCTION("""COMPUTED_VALUE"""),273695.0) -> 273695 | F28: =IFERROR(__xludf.DUMMYFUNCTION("""COMPUTED_VALUE"""),"PLN") -> PLN
A29: =IFERROR(__xludf.DUMMYFUNCTION("""COMPUTED_VALUE"""),"b757ff69-cc47-429e-a214-c270396205bf") -> b757ff69-cc47-429e-a214-c270396205bf | B29: =IFERROR(__xludf.DUMMYFUNCTION("""COMPUTED_VALUE"""),"Poznan") -> Poznan | C29: =IFERROR(__xludf.DUMMYFUNCTION("""COMPUTED_VALUE"""),45663.0) -> 45663 | D29: =IFERROR(__xludf.DUMMYFUNCTION("""COMPUTED_VALUE"""),56.0) -> 56 | E29: =IFERROR(__xludf.DUMMYFUNCTION("""COMPUTED_VALUE"""),181944.0) -> 181944 | F29: =IFERROR(__xludf.DUMMYFUNCTION("""COMPUTED_VALUE"""),"PLN") -> PLN
A30: =IFERROR(__xludf.DUMMYFUNCTION("""COMPUTED_VALUE"""),"f295b181-360f-4d85-b6ae-d32ea9493b80") -> f295b181-360f-4d85-b6ae-d32ea9493b80 | B30: =IFERROR(__xludf.DUMMYFUNCTION("""COMPUTED_VALUE"""),"Warsaw") -> Warsaw | C30: =IFERROR(__xludf.DUMMYFUNCTION("""COMPUTED_VALUE"""),45663.0) -> 45663 | D30: =IFERROR(__xludf.DUMMYFUNCTION("""COMPUTED_VALUE"""),61.0) -> 61 | E30: =IFERROR(__xludf.DUMMYFUNCTION("""COMPUTED_VALUE"""),263764.0) -> 263764 | F30: =IFERROR(__xludf.DUMMYFUNCTION("""COMPUTED_VALUE"""),"PLN") -> PLN
A31: =IFERROR(__xludf.DUMMYFUNCTION("""COMPUTED_VALUE"""),"9acdc63d-7516-45b9-b49c-032c92cca905") -> 9acdc63d-7516-45b9-b49c-032c92cca905 | B31: =IFERROR(__xludf.DUMMYFUNCTION("""COMPUTED_VALUE"""),"Poznan") -> Poznan | C31: =IFERROR(__xludf.DUMMYFUNCTION("""COMPUTED_VALUE"""),45663.0) -> 45663 | D31: =IFERROR(__xludf.DUMMYFUNCTION("""COMPUTED_VALUE"""),68.0) -> 68 | E31: =IFERROR(__xludf.DUMMYFUNCTION("""COMPUTED_VALUE"""),268804.0) -> 268804 | F31: =IFERROR(__xludf.DUMMYFUNCTION("""COMPUTED_VALUE"""),"PLN") -> PLN
A32: =IFERROR(__xludf.DUMMYFUNCTION("""COMPUTED_VALUE"""),"4eeddb18-7bab-484c-94e3-c265e0ab4fd8") -> 4eeddb18-7bab-484c-94e3-c265e0ab4fd8 | B32: =IFERROR(__xludf.DUMMYFUNCTION("""COMPUTED_VALUE"""),"Krakow") -> Krakow | C32: =IFERROR(__xludf.DUMMYFUNCTION("""COMPUTED_VALUE"""),45663.0) -> 45663 | D32: =IFERROR(__xludf.DUMMYFUNCTION("""COMPUTED_VALUE"""),57.0) -> 57 | E32: =IFERROR(__xludf.DUMMYFUNCTION("""COMPUTED_VALUE"""),212211.0) -> 212211 | F32: =IFERROR(__xludf.DUMMYFUNCTION("""COMPUTED_VALUE"""),"PLN") -> PLN
A33: =IFERROR(__xludf.DUMMYFUNCTION("""COMPUTED_VALUE"""),"67e81f84-545f-4bfb-ab8e-07ae6aea19a9") -> 67e81f84-545f-4bfb-ab8e-07ae6aea19a9 | B33: =IFERROR(__xludf.DUMMYFUNCTION("""COMPUTED_VALUE"""),"Krakow") -> Krakow | C33: =IFERROR(__xludf.DUMMYFUNCTION("""COMPUTED_VALUE"""),45663.0) -> 45663 | D33: =IFERROR(__xludf.DUMMYFUNCTION("""COMPUTED_VALUE"""),69.0) -> 69 | E33: =IFERROR(__xludf.DUMMYFUNCTION("""COMPUTED_VALUE"""),310431.0) -> 310431 | F33: =IFERROR(__xludf.DUMMYFUNCTION("""COMPUTED_VALUE"""),"PLN") -> PLN
A34: =IFERROR(__xludf.DUMMYFUNCTION("""COMPUTED_VALUE"""),"f12cb33a-d952-4c35-9f50-797eba8f7156") -> f12cb33a-d952-4c35-9f50-797eba8f7156 | B34: =IFERROR(__xludf.DUMMYFUNCTION("""COMPUTED_VALUE"""),"Gdansk") -> Gdansk | C34: =IFERROR(__xludf.DUMMYFUNCTION("""COMPUTED_VALUE"""),45663.0) -> 45663 | D34: =IFERROR(__xludf.DUMMYFUNCTION("""COMPUTED_VALUE"""),59.0) -> 59 | E34: =IFERROR(__xludf.DUMMYFUNCTION("""COMPUTED_VALUE"""),186499.0) -> 186499 | F34: =IFERROR(__xludf.DUMMYFUNCTION("""COMPUTED_VALUE"""),"PLN") -> PLN
A35: =IFERROR(__xludf.DUMMYFUNCTION("""COMPUTED_VALUE"""),"6918fb7f-1c4d-4525-a24a-bc5c952a330e") -> 6918fb7f-1c4d-4525-a24a-bc5c952a330e | B35: =IFERROR(__xludf.DUMMYFUNCTION("""COMPUTED_VALUE"""),"Lodz") -> Lodz | C35: =IFERROR(__xludf.DUMMYFUNCTION("""COMPUTED_VALUE"""),45663.0) -> 45663 | D35: =IFERROR(__xludf.DUMMYFUNCTION("""COMPUTED_VALUE"""),60.0) -> 60 | E35: =IFERROR(__xludf.DUMMYFUNCTION("""COMPUTED_VALUE"""),222240.0) -> 222240 | F35: =IFERROR(__xludf.DUMMYFUNCTION("""COMPUTED_VALUE"""),"PLN") -> PLN
A36: =IFERROR(__xludf.DUMMYFUNCTION("""COMPUTED_VALUE"""),"39f3a680-56e7-4b2b-a706-94319a1da61e") -> 39f3a680-56e7-4b2b-a706-94319a1da61e | B36: =IFERROR(__xludf.DUMMYFUNCTION("""COMPUTED_VALUE"""),"Warsaw") -> Warsaw | C36: =IFERROR(__xludf.DUMMYFUNCTION("""COMPUTED_VALUE"""),45670.0) -> 45670 | D36: =IFERROR(__xludf.DUMMYFUNCTION("""COMPUTED_VALUE"""),52.0) -> 52 | E36: =IFERROR(__xludf.DUMMYFUNCTION("""COMPUTED_VALUE"""),172016.0) -> 172016 | F36: =IFERROR(__xludf.DUMMYFUNCTION("""COMPUTED_VALUE"""),"PLN") -> PLN
A37: =IFERROR(__xludf.DUMMYFUNCTION("""COMPUTED_VALUE"""),"13ba2434-3f15-4a6c-8fb2-971d4edbc878") -> 13ba2434-3f15-4a6c-8fb2-971d4edbc878 | B37: =IFERROR(__xludf.DUMMYFUNCTION("""COMPUTED_VALUE"""),"Gdansk") -> Gdansk | C37: =IFERROR(__xludf.DUMMYFUNCTION("""COMPUTED_VALUE"""),45670.0) -> 45670 | D37: =IFERROR(__xludf.DUMMYFUNCTION("""COMPUTED_VALUE"""),63.0) -> 63 | E37: =IFERROR(__xludf.DUMMYFUNCTION("""COMPUTED_VALUE"""),255906.0) -> 255906 | F37: =IFERROR(__xludf.DUMMYFUNCTION("""COMPUTED_VALUE"""),"PLN") -> PLN
A38: =IFERROR(__xludf.DUMMYFUNCTION("""COMPUTED_VALUE"""),"63dc8854-5507-4bbc-b2e0-73e312a05bef") -> 63dc8854-5507-4bbc-b2e0-73e312a05bef | B38: =IFERROR(__xludf.DUMMYFUNCTION("""COMPUTED_VALUE"""),"Warsaw") -> Warsaw | C38: =IFERROR(__xludf.DUMMYFUNCTION("""COMPUTED_VALUE"""),45670.0) -> 45670 | D38: =IFERROR(__xludf.DUMMYFUNCTION("""COMPUTED_VALUE"""),59.0) -> 59 | E38: =IFERROR(__xludf.DUMMYFUNCTION("""COMPUTED_VALUE"""),182428.0) -> 182428 | F38: =IFERROR(__xludf.DUMMYFUNCTION("""COMPUTED_VALUE"""),"PLN") -> PLN
A39: =IFERROR(__xludf.DUMMYFUNCTION("""COMPUTED_VALUE"""),"f66db0dd-6f7d-4438-a70f-3a452f276824") -> f66db0dd-6f7d-4438-a70f-3a452f276824 | B39: =IFERROR(__xludf.DUMMYFUNCTION("""COMPUTED_VALUE"""),"Warsaw") -> Warsaw | C39: =IFERROR(__xludf.DUMMYFUNCTION("""COMPUTED_VALUE"""),45670.0) -> 45670 | D39: =IFERROR(__xludf.DUMMYFUNCTION("""COMPUTED_VALUE"""),58.0) -> 58 | E39: =IFERROR(__xludf.DUMMYFUNCTION("""COMPUTED_VALUE"""),198824.0) -> 198824 | F39: =IFERROR(__xludf.DUMMYFUNCTION("""COMPUTED_VALUE"""),"PLN") -> PLN
A40: =IFERROR(__xludf.DUMMYFUNCTION("""COMPUTED_VALUE"""),"482ef93a-3192-48da-b5a7-fdec50c860b6") -> 482ef93a-3192-48da-b5a7-fdec50c860b6 | B40: =IFERROR(__xludf.DUMMYFUNCTION("""COMPUTED_VALUE"""),"Poznan") -> Poznan | C40: =IFERROR(__xludf.DUMMYFUNCTION("""COMPUTED_VALUE"""),45670.0) -> 45670 | D40: =IFERROR(__xludf.DUMMYFUNCTION("""COMPUTED_VALUE"""),64.0) -> 64 | E40: =IFERROR(__xludf.DUMMYFUNCTION("""COMPUTED_VALUE"""),283648.0) -> 283648 | F40: =IFERROR(__xludf.DUMMYFUNCTION("""COMPUTED_VALUE"""),"PLN") -> PLN
...

Sheet Formulas
A1: Country | B1: Nr of traders | C1: Overall gross bookings | D1: Average amount of failed transactions per country | E1: Currency
A2: =IFERROR(__xludf.DUMMYFUNCTION("UNIQUE(FILTER(Data!B:B,Data!D:D=Data!D1444))"),"Poland") -> Poland | B2: =COUNTIFS(Data!$B$2:$B$1444,$A2,Data!$D$2:$D$1444,Data!$D$1444) -> 104 | C2: =SUMPRODUCT((Data!$B$2:$B$1444=$A2)*(Data!$D$2:$D$1444=Data!$D$1444)*(Data!$E$2:$E$1444*Data!$G$2:$G$1444)) -> 13069572 | D2: =(SUMPRODUCT((Data!$B$2:$B$1444=$A2)*(Data!$D$2:$D$1444=Data!$D$1444)*(Data!$F$2:$F$1444)))/B2 -> 2.6634615 | E2: =VLOOKUP($A2,'Currency Table'!$M$3:$N$6,2, FALSE) -> PLN
A3: =IFERROR(__xludf.DUMMYFUNCTION("""COMPUTED_VALUE"""),"UK") -> UK | B3: =COUNTIFS(Data!$B$2:$B$1444,$A3,Data!$D$2:$D$1444,Data!$D$1444) -> 72 | C3: =SUMPRODUCT((Data!$B$2:$B$1444=$A3)*(Data!$D$2:$D$1444=Data!$D$1444)*(Data!$E$2:$E$1444*Data!$G$2:$G$1444)) -> 2200675 | D3: =(SUMPRODUCT((Data!$B$2:$B$1444=$A3)*(Data!$D$2:$D$1444=Data!$D$1444)*(Data!$F$2:$F$1444)))/B3 -> 2.3888889 | E3: =VLOOKUP($A3,'Currency Table'!$M$3:$N$6,2, FALSE) -> GBP
A4: =IFERROR(__xludf.DUMMYFUNCTION("""COMPUTED_VALUE"""),"France") -> France | B4: =COUNTIFS(Data!$B$2:$B$1444,$A4,Data!$D$2:$D$1444,Data!$D$1444) -> 94 | C4: =SUMPRODUCT((Data!$B$2:$B$1444=$A4)*(Data!$D$2:$D$1444=Data!$D$1444)*(Data!$E$2:$E$1444*Data!$G$2:$G$1444)) -> 2858334 | D4: =(SUMPRODUCT((Data!$B$2:$B$1444=$A4)*(Data!$D$2:$D$1444=Data!$D$1444)*(Data!$F$2:$F$1444)))/B4 -> 2.393617 | E4: =VLOOKUP($A4,'Currency Table'!$M$3:$N$6,2, FALSE) -> EUR
A5: =IFERROR(__xludf.DUMMYFUNCTION("""COMPUTED_VALUE"""),"Spain") -> Spain | B5: =COUNTIFS(Data!$B$2:$B$1444,$A5,Data!$D$2:$D$1444,Data!$D$1444) -> 93 | C5: =SUMPRODUCT((Data!$B$2:$B$1444=$A5)*(Data!$D$2:$D$1444=Data!$D$1444)*(Data!$E$2:$E$1444*Data!$G$2:$G$1444)) -> 2398791 | D5: =(SUMPRODUCT((Data!$B$2:$B$1444=$A5)*(Data!$D$2:$D$1444=Data!$D$1444)*(Data!$F$2:$F$1444)))/B5 -> 2.4731183 | E5: =VLOOKUP($A5,'Currency Table'!$M$3:$N$6,2, FALSE) -> EUR

Sheet Pivot Table

Sheet Analysis
B1: Week | C1: Overall gross bookings | D1: Transactions overall
B2: 45663 | C2: =SUMPRODUCT((Data!$B$2:$B$1444="Poland")*(Data!$D$2:$D$1444=Data!$D$2)*(Data!$G$2:$G$1444)) -> 259194 | D2: =SUMPRODUCT((Data!$B$2:$B$1444="Poland")*(Data!$D$2:$D$1444=Data!$D$2)*(Data!$E$2:$E$1444)) -> 3872
B3: 45670 | C3: =SUMPRODUCT((Data!$B$2:$B$1444="Poland")*(Data!$D$2:$D$1444=Data!$D$103)*(Data!$G$2:$G$1444)) -> 242331 | D3: =SUMPRODUCT((Data!$B$2:$B$1444="Poland")*(Data!$D$2:$D$1444=Data!$D$103)*(Data!$E$2:$E$1444)) -> 3666
B4: 45677 | C4: =SUMPRODUCT((Data!$B$2:$B$1444="Poland")*(Data!$D$2:$D$1444=Data!$D$210)*(Data!$G$2:$G$1444)) -> 290224 | D4: =SUMPRODUCT((Data!$B$2:$B$1444="Poland")*(Data!$D$2:$D$1444=Data!$D$210)*(Data!$E$2:$E$1444)) -> 4561
B5: 45684 | C5: =SUMPRODUCT((Data!$B$2:$B$1444="Poland")*(Data!$D$2:$D$1444=Data!$D$1444)*(Data!$G$2:$G$1444)) -> 275687 | D5: =SUMPRODUCT((Data!$B$2:$B$1444="Poland")*(Data!$D$2:$D$1444=Data!$D$1444)*(Data!$E$2:$E$1444)) -> 4234
